Workbook

Sheet Dashboard de Progreso
B2: DASHBOARD DE PROGRESO DE JIRA
B3: Resumen automatizado extraído de tus datos
B5: TOTAL INCIDENCIAS | E5: COMPLETADAS | H5: EN PROGRESO | K5: PENDIENTES | N5: % AVANCE
B6: =COUNTA('Datos de Jira'!A2:A1000) -> 63 | E6: =COUNTIF('Datos de Jira'!D2:D1000, "Finalizada") + COUNTIF('Datos de Jira'!D2:D1000, "Done") + COUNTIF('Datos de Jira'!D2:D1000, "Completado") + COUNTIF('Datos de Jira'!D2:D1000, "Resuelta") + COUNTIF('Datos de Jira'!D2:D1000, "Cerrada") -> 46 | H6: =COUNTIF('Datos de Jira'!D2:D1000, "En curso") + COUNTIF('Datos de Jira'!D2:D1000, "In Progress") + COUNTIF('Datos de Jira'!D2:D1000, "En Progreso") -> 2 | K6: =COUNTIF('Datos de Jira'!D2:D1000, "Tareas por hacer") + COUNTIF('Datos de Jira'!D2:D1000, "To Do") + COUNTIF('Datos de Jira'!D2:D1000, "Abierta") + COUNTIF('Datos de Jira'!D2:D1000, "Idea") -> 15 | N6: =IF(B6>0, E6/B6, 0) -> 0.73015873
B9: Métricas por Estado
B10: Estado | C10: Cantidad | D10: Story Points
B11: Finalizada | C11: =COUNTIF('Datos de Jira'!D$2:D$1000, B11) -> 46 | D11: =SUMIF('Datos de Jira'!D$2:D$1000, B11, 'Datos de Jira'!G$2:G$1000) -> 163
B12: En curso | C12: =COUNTIF('Datos de Jira'!D$2:D$1000, B12) -> 2 | D12: =SUMIF('Datos de Jira'!D$2:D$1000, B12, 'Datos de Jira'!G$2:G$1000) -> 9
B13: Tareas por hacer | C13: =COUNTIF('Datos de Jira'!D$2:D$1000, B13) -> 13 | D13: =SUMIF('Datos de Jira'!D$2:D$1000, B13, 'Datos de Jira'!G$2:G$1000) -> 14
B14: Idea | C14: =COUNTIF('Datos de Jira'!D$2:D$1000, B14) -> 2 | D14: =SUMIF('Datos de Jira'!D$2:D$1000, B14, 'Datos de Jira'!G$2:G$1000) -> 4
B15: Total | C15: =SUM(C11:C14) -> 63 | D15: =SUM(D11:D14) -> 190
B18: Métricas por Prioridad
B19: Prioridad | C19: Cantidad | D19: Story Points
B20: High | C20: =COUNTIF('Datos de Jira'!E$2:E$1000, B20) -> 19 | D20: =SUMIF('Datos de Jira'!E$2:E$1000, B20, 'Datos de Jira'!G$2:G$1000) -> 60
B21: Highest | C21: =COUNTIF('Datos de Jira'!E$2:E$1000, B21) -> 23 | D21: =SUMIF('Datos de Jira'!E$2:E$1000, B21, 'Datos de Jira'!G$2:G$1000) -> 98
B22: Medium | C22: =COUNTIF('Datos de Jira'!E$2:E$1000, B22) -> 19 | D22: =SUMIF('Datos de Jira'!E$2:E$1000, B22, 'Datos de Jira'!G$2:G$1000) -> 27
B23: Lowest | C23: =COUNTIF('Datos de Jira'!E$2:E$1000, B23) -> 1 | D23: =SUMIF('Datos de Jira'!E$2:E$1000, B23, 'Datos de Jira'!G$2:G$1000) -> 4
B24: Low | C24: =COUNTIF('Datos de Jira'!E$2:E$1000, B24) -> 1 | D24: =SUMIF('Datos de Jira'!E$2:E$1000, B24, 'Datos de Jira'!G$2:G$1000) -> 1
B25: Total | C25: =SUM(C20:C24) -> 63 | D25: =SUM(D20:D24) -> 190

Sheet Datos de Jira
A1: Clave | B1: Resumen | C1: Tipo de Incidencia | D1: Estado | E1: Prioridad | F1: Responsable | G1: Story Points | H1: Fecha de Creación | I1: Fecha de Resolución
A2: SCRUM-69 | B2: Infraestructura del Microservicio Vambot | C2: Feature | D2: Finalizada | E2: High | F2: Pablo Mery | G2: 3 | H2: 25/may/26 3:16 AM | I2: 25/may/26 12:49 PM
A3: SCRUM-68 | B3: Pipeline de Extracción y Carga de Eventos | C3: Feature | D3: Finalizada | E3: High | F3: Freddy Gabriel Galarza Rios | G3: 3 | H3: 25/may/26 3:16 AM | I3: 25/may/26 12:49 PM
A4: SCRUM-67 | B4: Deploy e Infraestructura Cloud (AWS EC2) | C4: Feature | D4: Finalizada | E4: Highest | F4: Freddy Gabriel Galarza Rios | G4: 5 | H4: 25/may/26 3:16 AM | I4: 25/may/26 12:49 PM
A5: SCRUM-66 | B5: API REST de Listas Personales de Eventos | C5: Feature | D5: Finalizada | E5: Highest | F5: Freddy Gabriel Galarza Rios | G5: 4 | H5: 25/may/26 3:16 AM | I5: 25/may/26 12:49 PM
A6: SCRUM-65 | B6: API REST de Grupos Logísticos | C6: Feature | D6: Finalizada | E6: Highest | F6: Freddy Gabriel Galarza Rios | G6: 4 | H6: 25/may/26 3:16 AM | I6: 25/may/26 12:49 PM
A7: SCRUM-64 | B7: API REST de Eventos | C7: Feature | D7: Finalizada | E7: Highest | F7: Freddy Gabriel Galarza Rios | G7: 4 | H7: 25/may/26 3:16 AM | I7: 25/may/26 12:49 PM
A8: SCRUM-63 | B8: Autenticación y Sesiones (OAuth2 + JWT) | C8: Feature | D8: En curso | E8: High | F8: Pablo Mery | G8: 4 | H8: 25/may/26 3:16 AM
A9: SCRUM-62 | B9: Infraestructura Django y Docker | C9: Feature | D9: Finalizada | E9: Highest | F9: Freddy Gabriel Galarza Rios | G9: 5 | H9: 25/may/26 3:15 AM | I9: 25/may/26 12:47 PM
A10: SCRUM-61 | B10: Búsqueda semántica y respuesta LLM en endpoint /ask | C10: Historia | D10: Finalizada | E10: Highest | F10: Pablo Mery | G10: 5 | H10: 25/may/26 3:12 AM | I10: 25/may/26 3:28 AM
A11: SCRUM-60 | B11: Generar y almacenar embeddings de eventos con Gemini y pgvector | C11: Tarea | D11: Finalizada | E11: High | F11: Pablo Mery | G11: 4 | H11: 25/may/26 3:12 AM | I11: 25/may/26 3:28 AM
A12: SCRUM-59 | B12: Crear microservicio Vambot en FastAPI (puerto 8001) | C12: Tarea | D12: Finalizada | E12: Highest | F12: Pablo Mery | G12: 5 | H12: 25/may/26 3:12 AM | I12: 25/may/26 3:28 AM
A13: SCRUM-58 | B13: DataSeeder - inyectar eventos JSON en PostgreSQL | C13: Tarea | D13: Finalizada | E13: High | F13: Pablo Mery | G13: 4 | H13: 25/may/26 3:12 AM | I13: 25/may/26 3:28 AM
A14: SCRUM-57 | B14: Script scraper para Municipalidad de Providencia | C14: Tarea | D14: Finalizada | E14: Highest | F14: Freddy Gabriel Galarza Rios | G14: 5 | H14: 25/may/26 3:11 AM | I14: 25/may/26 3:28 AM
A15: SCRUM-56 | B15: Deploy del backend en AWS EC2 con Docker | C15: Tarea | D15: Finalizada | E15: Highest | F15: Freddy Gabriel Galarza Rios | G15: 5 | H15: 25/may/26 3:11 AM | I15: 25/may/26 3:49 AM
A16: SCRUM-55 | B16: Implementar DELETE para quitar eventos de listas personales | C16: Tarea | D16: Finalizada | E16: High | F16: Freddy Gabriel Galarza Rios | G16: 3 | H16: 25/may/26 3:11 AM | I16: 25/may/26 3:49 AM
A17: SCRUM-54 | B17: Implementar endpoints de eventos guardados/confirmados | C17: Historia | D17: Finalizada | E17: Medium | F17: Freddy Gabriel Galarza Rios | G17: 3 | H17: 25/may/26 3:11 AM | I17: 25/may/26 3:27 AM
A18: SCRUM-53 | B18: Implementar endpoints de grupos logísticos en Django | C18: Historia | D18: Finalizada | E18: Highest | F18: Freddy Gabriel Galarza Rios | G18: 5 | H18: 25/may/26 3:11 AM | I18: 25/may/26 3:49 AM
A19: SCRUM-52 | B19: Crear app eventos/ y endpoints REST de eventos | C19: Historia | D19: Finalizada | E19: Medium | F19: Sin asignar | G19: 3 | H19: 25/may/26 3:11 AM | I19: 25/may/26 3:27 AM
A20: SCRUM-51 | B20: Implementar autenticación Google OAuth2 y JWT en Django | C20: Historia | D20: Finalizada | E20: Highest | F20: Pablo Mery | G20: 4 | H20: 25/may/26 3:10 AM | I20: 25/may/26 3:49 AM
... A22: SCRUM-49 | B22: Configurar proyecto Django con Docker y PostgreSQL | C22: Tarea | D22: Finalizada | E22: Highest | F22: Freddy Gabriel Galarza Rios | G22: 5 | H22: 25/may/26 3:10 AM | I22: 25/may/26 3:48 AM
A23: SCRUM-48 | B23: Falta endpoint DELETE para quitar eventos de listas | C23: Error | D23: Tareas por hacer | E23: High | F23: Freddy Gabriel Galarza Rios | G23: 3 | H23: 25/may/26 2:03 AM
A24: SCRUM-47 | B24: Markers superpuestos causan parpadeo en el mapa | C24: Error | D24: Tareas por hacer | E24: Highest | F24: LUIS MANUEL NUNEZ TAPIA | G24: 5 | H24: 25/may/26 2:03 AM
A25: SCRUM-46 | B25: Configurar EAS Build y generar APK | C25: Tarea | D25: Finalizada | E25: High | F25: LUIS MANUEL NUNEZ TAPIA | G25: 5 | H25: 25/may/26 2:03 AM | I25: 25/may/26 3:49 AM
A26: SCRUM-45 | B26: BottomSheet - componente base reutilizable | C26: Tarea | D26: Finalizada | E26: Medium | F26: LUIS MANUEL NUNEZ TAPIA | G26: 2 | H26: 25/may/26 2:03 AM | I26: 25/may/26 3:27 AM
A27: SCRUM-44 | B27: Sistema de temas (useTheme) con dark mode automático | C27: Tarea | D27: Finalizada | E27: Medium | F27: LUIS MANUEL NUNEZ TAPIA | G27: 3 | H27: 25/may/26 2:03 AM | I27: 25/may/26 3:49 AM
A28: SCRUM-43 | B28: AIChatModal - interfaz de chat con Vambot | C28: Historia | D28: Finalizada | E28: High | F28: LUIS MANUEL NUNEZ TAPIA | G28: 3 | H28: 25/may/26 2:02 AM | I28: 25/may/26 3:48 AM
A29: SCRUM-42 | B29: SavedEventsContext sincronizado con backend | C29: Tarea | D29: Finalizada | E29: Highest | F29: LUIS MANUEL NUNEZ TAPIA | G29: 4 | H29: 25/may/26 2:02 AM | I29: 25/may/26 3:49 AM
A30: SCRUM-41 | B30: Pantalla de guardados con tarjetas diferenciadas | C30: Historia | D30: Finalizada | E30: Medium | F30: LUIS MANUEL NUNEZ TAPIA | G30: 2 | H30: 25/may/26 2:02 AM | I30: 25/may/26 3:27 AM
A31: SCRUM-40 | B31: RoutePanel con distancia, tiempo y modos de transporte | C31: Historia | D31: Finalizada | E31: High | F31: LUIS MANUEL NUNEZ TAPIA | G31: 4 | H31: 25/may/26 2:01 AM | I31: 25/may/26 3:49 AM
A32: SCRUM-39 | B32: JoinGroupModal - unirse a grupo con código manual | C32: Historia | D32: Finalizada | E32: Highest | F32: LUIS MANUEL NUNEZ TAPIA | G32: 5 | H32: 25/may/26 2:01 AM | I32: 25/may/26 3:49 AM
A33: SCRUM-38 | B33: EstadoModal para cambio de estado de miembro | C33: Historia | D33: Finalizada | E33: High | F33: LUIS MANUEL NUNEZ TAPIA | G33: 5 | H33: 25/may/26 2:01 AM | I33: 25/may/26 3:49 AM
A34: SCRUM-37 | B34: Pantalla de grupo con lista de miembros y estados | C34: Historia | D34: Finalizada | E34: Highest | F34: LUIS MANUEL NUNEZ TAPIA | G34: 3 | H34: 25/may/26 2:00 AM | I34: 25/may/26 3:48 AM
A35: SCRUM-36 | B35: Conectar eventos al backend real (USE_MOCK=false) | C35: Tarea | D35: Finalizada | E35: Highest | F35: LUIS MANUEL NUNEZ TAPIA | G35: 3 | H35: 25/may/26 2:00 AM | I35: 25/may/26 3:48 AM
A36: SCRUM-35 | B36: EventDetailSheet - detalle de evento en bottom sheet | C36: Historia | D36: Finalizada | E36: Highest | F36: LUIS MANUEL NUNEZ TAPIA | G36: 2 | H36: 25/may/26 2:00 AM | I36: 25/may/26 3:27 AM
... A40: SCRUM-31 | B40: Pantalla de Login con Google Sign-In | C40: Historia | D40: Finalizada | E40: Highest | F40: Pablo Mery | G40: 4 | H40: 25/may/26 1:59 AM | I40: 25/may/26 3:48 AM
A41: SCRUM-30 | B41: Eventos Guardados y Confirmados | C41: Epic | D41: Tareas por hacer | E41: High | F41: Sin asignar | G41: 0 | H41: 25/may/26 1:59 AM
A42: SCRUM-29 | B42: Navegación y Ruteo (RF-06) | C42: Epic | D42: Tareas por hacer | E42: High | F42: Sin asignar | G42: 0 | H42: 25/may/26 1:58 AM
A43: SCRUM-28 | B43: Definir atributos | C43: Tarea | D43: Finalizada | E43: Medium | F43: Sin asignar | G43: 3 | H43: 25/mar/26 10:27 PM | I43: 25/may/26 3:20 AM
A44: SCRUM-27 | B44: Normalizar la base de datos | C44: Tarea | D44: Finalizada | E44: Medium | F44: Sin asignar | G44: 4 | H44: 25/mar/26 10:26 PM | I44: 25/may/26 3:20 AM
...
